<?xml version="1.0"?>
<robot xmlns:xacro="http://www.ros.org/wiki/xacro" name="round_bot">
    
    <link name="base_footprint">
        
    </link>
    
    <joint name="base_link_joint" type="fixed">
        <parent link="base_footprint"/>
        <child link="base_link"/>
        <origin xyz="0.0 0.0 0.0" rpy="0.0 0.0 0.0"/>
    </joint>
    
    <link name="base_link">
        <visual>
            <origin xyz="0.0 0.0 0.12" rpy="0.0 0.0 0.0"/>
            <geometry>
                <cylinder radius="0.35" length="0.1"/>
            </geometry>
            <material name ="">
                <color rgba = "1.0 0.3 0.1 1.0"/>
            </material>
        </visual>
        <collision>
            <origin xyz="0.0 0.0 0.12" rpy="0.0 0.0 0.0"/>
            <geometry>
                <cylinder radius="0.35" length="0.1"/>
                <!-- <sphere radius="0.2"/>
                <contact_coefficients mu = "1" kp = "1e+13" kd = "1.0"/> -->
            </geometry>
        </collision>
    </link>

    <gazebo reference = "base_link">
        <material> Gazebo/Orange </material>
    </gazebo>

    <link name="back_caster_link">
        <visual>                     
            <geometry>
                <sphere radius="0.05"/>
            </geometry>
            <material name="">
                <color rgba="1.0 0.0 0.0 1.0"/>
            </material>
        </visual>
        <collision>
            <geometry>
                <sphere radius="0.05"/>
            </geometry>
        </collision>

        <!-- <inertial>
        <origin xyz="0 0 0" />
        <mass value="0.005" />
        <inertia ixx="0.001" ixy="0.0" ixz="0.0"
                iyy="0.001" iyz="0.0"
                izz="0.001" />
        </inertial> -->
    </link> 

    <gazebo reference = "caster_link">
        <material> Gazebo/Red</material>
    </gazebo> 

    <joint name="back_caster_joint" type="continuous">
        <parent link="base_link"/>
        <child link="back_caster_link"/>
        <origin xyz="0.0 0.25 0.04" rpy="0 0 0"/>
    </joint>

    <link name="front_caster_link">
        <visual>                     
            <geometry>
                <sphere radius="0.05"/>
            </geometry>
            <material name="">
                <color rgba="1.0 0.0 0.0 1.0"/>
            </material>
        </visual>
        <collision>
            <geometry>
                <sphere radius="0.05"/>
            </geometry>
        </collision>

        <!-- <inertial>
        <origin xyz="0 0 0" />
        <mass value="0.005" />
        <inertia ixx="0.001" ixy="0.0" ixz="0.0"
                iyy="0.001" iyz="0.0"
                izz="0.001" />
        </inertial> -->
    </link> 

    <gazebo reference = "caster_link">
        <material> Gazebo/Red</material>
    </gazebo> 

    <joint name="front_caster_joint" type="continuous">
        <parent link="base_link"/>
        <child link="front_caster_link"/>
        <origin xyz="0.0 -0.25 0.04" rpy="0 0 0"/>
    </joint>

    <link name="left_wheel">
        <visual>
            <geometry>
                <cylinder radius="0.08" length="0.05"/>
            </geometry>
            <material name = "">
                <color rgba = "1.0 0.0 0.0 1.0"/>
            </material>
        </visual>
        <collision>
            <geometry>
                <sphere radius="0.0"/>
                <contact_coefficients mu = "1" kp = "1e+13" kd = "1.0"/>
            </geometry>
        </collision>
    </link>

    <joint name="left_wheel_joint" type="continuous">
        <parent link="base_link"/>
        <child link="left_wheel"/>
        <axis xyz="0 0 1.0"/>
        <origin xyz="0.25 0 0.075" rpy="1.57 0 1.57"/>
    </joint>

        <link name="right_wheel">
        <visual>
            <geometry>
                <cylinder radius="0.08" length="0.05"/>
            </geometry>
            <material name = "">
                <color rgba = "1.0 0.0 0.0 1.0"/>
            </material>
        </visual>
        <collision>
            <geometry>
                <sphere radius="0.0"/>
                <contact_coefficients mu = "1" kp = "1e+13" kd = "1.0"/>
            </geometry>
        </collision>
    </link>

    <joint name="right_wheel_joint" type="continuous">
        <parent link="base_link"/>
        <child link="right_wheel"/>
        <axis xyz="0 0 1.0"/>
        <origin xyz="-0.25 0 0.075" rpy="1.57 0 1.57"/>
    </joint>

    <link name="mount_link">
        <visual>                     
            <geometry>
                <cylinder radius="0.08" length="0.1"/>
            </geometry>
            <material name="">
                <color rgba="0.0 0.0 0.0 1.0"/>
            </material>
        </visual>
        <collision>
            <geometry>
                <cylinder radius="0.08" length="0.1"/>
            </geometry>
        </collision>
    </link> 

    <gazebo reference = "mount_link">
        <material> Gazebo/Black</material>
    </gazebo>

    <joint name="mount_joint" type="fixed">
        <parent link="base_link"/>
        <child link="mount_link"/>
        <origin xyz="0.0 -0.2 0.2" rpy="0.0 0.0 0.0"/>
    </joint>
    
</robot>